Workbook
Name annualH2kg: '計算'!$C$12
Name capacityKW: '入力'!$B$9
Name capexPerKW: '入力'!$B$12
Name cf: '入力'!$B$17
Name comprCapex: '入力'!$B$43
Name comprSEC: '入力'!$B$44
Name degradation: '入力'!$B$19
Name elecPrice: '入力'!$B$22
Name fx: '入力'!$B$35
Name grossPos: '計算'!$C$32
Name HHV: '定数・前提'!$B$6
Name hoursPerYear: '定数・前提'!$B$7
Name inclCompr: '入力'!$B$42
Name installFactor: '入力'!$B$13
Name lcohNm3: '計算'!$C$34
Name lcohPerKg: '計算'!$C$33
Name lcohUSD: '計算'!$C$35
Name lifetime: '入力'!$B$18
Name NM3perKG: '定数・前提'!$B$5
Name now_p_capex: '計算'!$C$24
Name now_p_compr: '計算'!$C$29
Name now_p_elec: '計算'!$C$27
Name now_p_o2: '計算'!$C$31
Name now_p_om: '計算'!$C$26
Name now_p_stack: '計算'!$C$25
Name now_p_subsidy: '計算'!$C$30
Name now_p_water: '計算'!$C$28
Name o2Credit: '入力'!$B$39
Name omPct: '入力'!$B$26
Name presetCapex: '定数・前提'!$B$13:$B$16
Name presetNames: '定数・前提'!$A$13:$A$16
Name presetOM: '定数・前提'!$F$13:$F$16
Name presetSEC: '定数・前提'!$C$13:$C$16
Name presetStackLife: '定数・前提'!$E$13:$E$16
Name presetStackShare: '定数・前提'!$D$13:$D$16
Name secNm3: '入力'!$B$23
Name stackLifeH: '入力'!$B$31
Name stackShare: '入力'!$B$14
Name subsidy: '入力'!$B$38
Name target2030: '定数・前提'!$B$8
Name target2050: '定数・前提'!$B$9
Name tech: '入力'!$B$6
Name wacc: '入力'!$B$34
Name waterPrice: '入力'!$B$28
Name waterUse: '入力'!$B$27

Sheet 入力
A1: 水電解 水素製造コスト 試算ツール ― 入力
A2: 黄色セルだけ編集してください。結果は『結果』シートに自動反映（グラフ付き）。
A3: 凡例: | B3: 入力 | C3: 定数 | D3: 計算結果（自動）
A5: 方式プリセット参照
A6: 方式（参考値の表示用） | B6: PEM | D6: 右の入力欄に手動で値を入れます。選択方式の代表値は各行の備考に表示。
A8: ① 装置・規模
A9: 定格電力 | B9: 1000 | C9: kW | D9: システムへの定格入力電力
A11: ② CAPEX（設備費）
A12: システムCAPEX単価 | B12: 165000 | C12: 円/kW | D12: =("参考("&tech&"): "&TEXT(INDEX(presetCapex,MATCH(tech,presetNames,0)),"#,##0.###")&" 円/kW") -> 0
A13: 据付・建設係数 | B13: 20 | C13: % | D13: システム費に上乗せ
A14: スタック比率（対システム） | B14: 45 | C14: % | D14: =("参考("&tech&"): "&TEXT(INDEX(presetStackShare,MATCH(tech,presetNames,0)),"#,##0.###")&" %") -> 0
A16: ③ 稼働プロファイル
A17: 設備利用率（稼働率） | B17: 46 | C17: % | D17: 稼働率×8760 = 年間稼働時間
A18: 設備寿命 | B18: 20 | C18: 年
A19: 劣化率（電力原単位の上昇） | B19: 0 | C19: %/年 | D19: 0で劣化なし
A21: ④ 電力
A22: 電力単価 | B22: 15 | C22: 円/kWh | D22: LCOHの最大要素
A23: 電力原単位（SEC） | B23: 5 | C23: kWh/Nm³ | D23: =("参考("&tech&"): "&TEXT(INDEX(presetSEC,MATCH(tech,presetNames,0)),"#,##0.###")&" kWh/Nm³") -> 0
A25: ⑤ O&M・水
A26: 固定O&M（対CAPEX） | B26: 3.5 | C26: %/年 | D26: =("参考("&tech&"): "&TEXT(INDEX(presetOM,MATCH(tech,presetNames,0)),"#,##0.###")&" %/年") -> 0
A27: 水消費 | B27: 1.4 | C27: L/Nm³
A28: 水単価 | B28: 300 | C28: 円/m³
A30: ⑥ スタック
A31: スタック寿命 | B31: 70000 | C31: 時間(h) | D31: =("参考("&tech&"): "&TEXT(INDEX(presetStackLife,MATCH(tech,presetNames,0)),"#,##0.###")&" 時間(h)") -> 0
A33: ⑦ 財務
A34: 割引率（WACC） | B34: 7 | C34: % | D34: 資本回収係数CRFに使用
A35: 為替 | B35: 150 | C35: 円/$ | D35: $表示用
A37: ⑧ 補助金・副生酸素（任意）
A38: 補助金 | B38: 0 | C38: 円/Nm³ | D38: コストから差引
A39: 副生酸素 販売益 | B39: 0 | C39: 円/Nm³ | D39: コストから差引
A41: ⑨ 圧縮・出荷（任意）
A42: 圧縮・出荷を含める | B42: 0 | C42: 1=含/0=否 | D42: 1で下の2項目を反映
A43: 圧縮機等CAPEX（総額） | B43: 50000000 | C43: 円
A44: 圧縮 電力原単位 | B44: 3 | C44: kWh/kg

Sheet 結果
A1: 水電解 水素製造コスト 試算結果
A2: 数値は『入力』を変えると自動更新。方式比較の積み上げ・構成比・感度をグラフ表示。
A4: 水素製造コスト (LCOH)
A5: =lcohNm3 -> 109.89426 | C5: 円/Nm³
A6: 円/kg | B6: =lcohPerKg -> 1223.1232
A7: $/kg | B7: =lcohUSD -> 8.1541544
A9: 年間生産量 | B9: =annualH2kg*NM3perKG -> 805920 | C9: Nm³/年
B10: =annualH2kg/1000 -> 72.409704 | C10: t/年
A12: 電力費シェア | B12: =now_p_elec/grossPos -> 0.6824742
A13: 2030目標差 | B13: =lcohNm3-target2030 -> 79.894265 | C13: 円/Nm³
A16: 内訳 | B16: 円/Nm³ | C16: 円/kg | E16: $/kg | F16: 構成比
A17: 設備費(CAPEX) | B17: =now_p_capex/NM3perKG -> 23.190638 | C17: =now_p_capex -> 258.11181 | E17: =now_p_capex/fx -> 1.7207454 | F17: =now_p_capex/grossPos -> 0.21102683
A18: スタック交換 | B18: =now_p_stack/NM3perKG -> 2.6847578 | C18: =now_p_stack -> 29.881354 | E18: =now_p_stack/fx -> 0.19920903 | F18: =now_p_stack/grossPos -> 0.024430372
A19: 固定O&M | B19: =now_p_om/NM3perKG -> 8.5988684 | C19: =now_p_om -> 95.705405 | E19: =now_p_om/fx -> 0.63803603 | F19: =now_p_om/grossPos -> 0.078246744
A20: 電力費 | B20: =now_p_elec/NM3perKG -> 75 | C20: =now_p_elec -> 834.75 | E20: =now_p_elec/fx -> 5.565 | F20: =now_p_elec/grossPos -> 0.6824742
A21: 水費 | B21: =now_p_water/NM3perKG -> 0.42 | C21: =now_p_water -> 4.6746 | E21: =now_p_water/fx -> 0.031164 | F21: =now_p_water/grossPos -> 0.0038218555
A22: 圧縮・出荷 | B22: =now_p_compr/NM3perKG -> 0 | C22: =now_p_compr -> 0 | E22: =now_p_compr/fx -> 0 | F22: =now_p_compr/grossPos -> 0
A23: 補助金 | B23: =now_p_subsidy/NM3perKG -> 0 | C23: =now_p_subsidy -> 0 | E23: =now_p_subsidy/fx -> 0 | F23: =now_p_subsidy/grossPos -> 0
A24: 副生酸素 | B24: =now_p_o2/NM3perKG -> 0 | C24: =now_p_o2 -> 0 | E24: =now_p_o2/fx -> 0 | F24: =now_p_o2/grossPos -> 0
A25: 合計 LCOH | B25: =lcohNm3 -> 109.89426 | C25: =lcohPerKg -> 1223.1232 | E25: =lcohUSD -> 8.1541544

Sheet 定数・前提
A1: 定数・前提（固定値／プリセット）
A2: 青セルは定数・前提。通常は変更不要（必要なら編集可）。方式プリセットは『入力』の参考列で参照されます。
A4: 物理定数・換算
A5: kg→Nm³ 換算 | B5: 11.13 | C5: Nm³/kg | D5: 0℃,1atm 密度0.0899kg/Nm³
A6: 水素 高位発熱量 | B6: 39.4 | C6: kWh/kg | D6: 効率算定用 (141.8 MJ/kg)
A7: 年間時間 | B7: 8760 | C7: h/年 | D7: 8760 = 24×365
A8: 日本 供給コスト目標 2030 | B8: 30 | C8: 円/Nm³ | D8: 経産省/NEDO
A9: 日本 供給コスト目標 2050 | B9: 20 | C9: 円/Nm³ | D9: 経産省/NEDO
A11: 方式プリセット（代表値・編集可）
A12: 方式 | B12: CAPEX単価(円/kW) | C12: SEC(kWh/Nm³) | D12: スタック比率(%) | E12: スタック寿命(h) | F12: O&M(%/年)
A13: アルカリ | B13: 130000 | C13: 4.8 | D13: 35 | E13: 80000 | F13: 3
A14: PEM | B14: 165000 | C14: 5 | D14: 45 | E14: 70000 | F14: 3.5
A15: SOEC | B15: 330000 | C15: 3.8 | D15: 50 | E15: 40000 | F15: 4
A16: AEM | B16: 140000 | C16: 4.8 | D16: 40 | E16: 30000 | F16: 3

Sheet 計算
A1: 計算（LCOHエンジン）
A2: 数式は『入力』『定数・前提』の名前を参照。編集不要。
A4: 項目 | C4: 現在 | D4: アルカリ | E4: PEM | F4: SOEC | G4: AEM
A5: r=WACC | C5: =wacc/100 -> 0.07 | D5: =wacc/100 -> 0.07 | E5: =wacc/100 -> 0.07 | F5: =wacc/100 -> 0.07 | G5: =wacc/100 -> 0.07
A6: 寿命N | C6: =lifetime -> 20 | D6: =lifetime -> 20 | E6: =lifetime -> 20 | F6: =lifetime -> 20 | G6: =lifetime -> 20
A7: 資本回収係数CRF | C7: =IF(C5<=0,1/C6,C5*(1+C5)^C6/((1+C5)^C6-1)) -> 0.094392926 | D7: =IF(D5<=0,1/D6,D5*(1+D5)^D6/((1+D5)^D6-1)) -> 0.094392926 | E7: =IF(E5<=0,1/E6,E5*(1+E5)^E6/((1+E5)^E6-1)) -> 0.094392926 | F7: =IF(F5<=0,1/F6,F5*(1+F5)^F6/((1+F5)^F6-1)) -> 0.094392926 | G7: =IF(G5<=0,1/G6,G5*(1+G5)^G6/((1+G5)^G6-1)) -> 0.094392926
A8: 年間稼働時間 | C8: =cf/100*hoursPerYear -> 4029.6 | D8: =cf/100*hoursPerYear -> 4029.6 | E8: =cf/100*hoursPerYear -> 4029.6 | F8: =cf/100*hoursPerYear -> 4029.6 | G8: =cf/100*hoursPerYear -> 4029.6
A9: SEC(kWh/kg) | C9: =secNm3*NM3perKG -> 55.65 | D9: ='定数・前提'!$C$13*NM3perKG -> 53.424 | E9: ='定数・前提'!$C$14*NM3perKG -> 55.65 | F9: ='定数・前提'!$C$15*NM3perKG -> 42.294 | G9: ='定数・前提'!$C$16*NM3perKG -> 53.424
A10: 劣化係数 | C10: =1+(degradation/100)*(C6/2) -> 1 | D10: =1+(degradation/100)*(D6/2) -> 1 | E10: =1+(degradation/100)*(E6/2) -> 1 | F10: =1+(degradation/100)*(F6/2) -> 1 | G10: =1+(degradation/100)*(G6/2) -> 1
A11: 実効SEC | C11: =C9*C10 -> 55.65 | D11: =D9*D10 -> 53.424 | E11: =E9*E10 -> 55.65 | F11: =F9*F10 -> 42.294 | G11: =G9*G10 -> 53.424
A12: 年間H2(kg) | C12: =IF(C8>0,capacityKW*C8/C11,0) -> 72409.704 | D12: =IF(D8>0,capacityKW*D8/D11,0) -> 75426.774 | E12: =IF(E8>0,capacityKW*E8/E11,0) -> 72409.704 | F12: =IF(F8>0,capacityKW*F8/F11,0) -> 95275.926 | G12: =IF(G8>0,capacityKW*G8/G11,0) -> 75426.774
A13: システムCAPEX | C13: =capacityKW*capexPerKW -> 165000000 | D13: =capacityKW*'定数・前提'!$B$13 -> 130000000 | E13: =capacityKW*'定数・前提'!$B$14 -> 165000000 | F13: =capacityKW*'定数・前提'!$B$15 -> 330000000 | G13: =capacityKW*'定数・前提'!$B$16 -> 140000000
A14: 総CAPEX(据付込) | C14: =C13*(1+installFactor/100) -> 198000000 | D14: =D13*(1+installFactor/100) -> 156000000 | E14: =E13*(1+installFactor/100) -> 198000000 | F14: =F13*(1+installFactor/100) -> 396000000 | G14: =G13*(1+installFactor/100) -> 168000000
A15: CAPEX年経費 | C15: =C14*C7 -> 18689799 | D15: =D14*D7 -> 14725296 | E15: =E14*E7 -> 18689799 | F15: =F14*F7 -> 37379599 | G15: =G14*G7 -> 15858012
A16: 固定O&M(円/年) | C16: =C14*omPct/100 -> 6930000 | D16: =D14*'定数・前提'!$F$13/100 -> 4680000 | E16: =E14*'定数・前提'!$F$14/100 -> 6930000 | F16: =F14*'定数・前提'!$F$15/100 -> 15840000 | G16: =G14*'定数・前提'!$F$16/100 -> 5040000
A17: スタック費/回 | C17: =C13*stackShare/100 -> 74250000 | D17: =D13*'定数・前提'!$D$13/100 -> 45500000 | E17: =E13*'定数・前提'!$D$14/100 -> 74250000 | F17: =F13*'定数・前提'!$D$15/100 -> 165000000 | G17: =G13*'定数・前提'!$D$16/100 -> 56000000
A18: 交換周期(年) | C18: =IF(C8>0,stackLifeH/C8,1E+09) -> 17.371451 | D18: =IF(D8>0,'定数・前提'!$E$13/D8,1E+09) -> 19.853087 | E18: =IF(E8>0,'定数・前提'!$E$14/E8,1E+09) -> 17.371451 | F18: =IF(F8>0,'定数・前提'!$E$15/F8,1E+09) -> 9.9265436 | G18: =IF(G8>0,'定数・前提'!$E$16/G8,1E+09) -> 7.4449077
A19: 交換回数 | C19: =MAX(0,CEILING(C6/C18,1)-1) -> 1 | D19: =MAX(0,CEILING(D6/D18,1)-1) -> 1 | E19: =MAX(0,CEILING(E6/E18,1)-1) -> 1 | F19: =MAX(0,CEILING(F6/F18,1)-1) -> 2 | G19: =MAX(0,CEILING(G6/G18,1)-1) -> 2
A20: 割引率^(-周期) | C20: =(1+C5)^(-C18) -> 0.30871742 | D20: =(1+D5)^(-D18) -> 0.26100048 | E20: =(1+E5)^(-E18) -> 0.30871742 | F20: =(1+F5)^(-F18) -> 0.51088206 | G20: =(1+G5)^(-G18) -> 0.60428315
A21: 交換費PV | C21: =IF(C5<=0,C17*C19,IF(C19<=0,0,C17*C20*(1-C20^C19)/(1-C20))) -> 22922269 | D21: =IF(D5<=0,D17*D19,IF(D19<=0,0,D17*D20*(1-D20^D19)/(1-D20))) -> 11875522 | E21: =IF(E5<=0,E17*E19,IF(E19<=0,0,E17*E20*(1-E20^E19)/(1-E20))) -> 22922269 | F21: =IF(F5<=0,F17*F19,IF(F19<=0,0,F17*F20*(1-F20^F19)/(1-F20))) -> 1.2736062e+08 | G21: =IF(G5<=0,G17*G19,IF(G19<=0,0,G17*G20*(1-G20^G19)/(1-G20))) -> 54288712
A22: スタック年経費 | C22: =C21*C7 -> 2163700 | D22: =D21*D7 -> 1120965.2 | E22: =E21*E7 -> 2163700 | F22: =F21*F7 -> 12021941 | G22: =G21*G7 -> 5124470.4
A23: 圧縮(円/kg) | C23: =IF(inclCompr=1,IF(C12>0,(comprCapex*C7+comprCapex*omPct/100)/C12,0)+elecPrice*comprSEC,0) -> 0 | D23: =IF(inclCompr=1,IF(D12>0,(comprCapex*D7+comprCapex*'定数・前提'!$F$13/100)/D12,0)+elecPrice*comprSEC,0) -> 0 | E23: =IF(inclCompr=1,IF(E12>0,(comprCapex*E7+comprCapex*'定数・前提'!$F$14/100)/E12,0)+elecPrice*comprSEC,0) -> 0 | F23: =IF(inclCompr=1,IF(F12>0,(comprCapex*F7+comprCapex*'定数・前提'!$F$15/100)/F12,0)+elecPrice*comprSEC,0) -> 0 | G23: =IF(inclCompr=1,IF(G12>0,(comprCapex*G7+comprCapex*'定数・前提'!$F$16/100)/G12,0)+elecPrice*comprSEC,0) -> 0
A24: 設備費(円/kg) | C24: =IF(C12>0,C15/C12,0) -> 258.11181 | D24: =IF(D12>0,D15/D12,0) -> 195.22638 | E24: =IF(E12>0,E15/E12,0) -> 258.11181 | F24: =IF(F12>0,F15/F12,0) -> 392.32994 | G24: =IF(G12>0,G15/G12,0) -> 210.2438
A25: スタック交換(円/kg) | C25: =IF(C12>0,C22/C12,0) -> 29.881354 | D25: =IF(D12>0,D22/D12,0) -> 14.861636 | E25: =IF(E12>0,E22/E12,0) -> 29.881354 | F25: =IF(F12>0,F22/F12,0) -> 126.18026 | G25: =IF(G12>0,G22/G12,0) -> 67.939673
A26: 固定O&M(円/kg) | C26: =IF(C12>0,C16/C12,0) -> 95.705405 | D26: =IF(D12>0,D16/D12,0) -> 62.046933 | E26: =IF(E12>0,E16/E12,0) -> 95.705405 | F26: =IF(F12>0,F16/F12,0) -> 166.25396 | G26: =IF(G12>0,G16/G12,0) -> 66.819774
A27: 電力費(円/kg) | C27: =elecPrice*C11 -> 834.75 | D27: =elecPrice*D11 -> 801.36 | E27: =elecPrice*E11 -> 834.75 | F27: =elecPrice*F11 -> 634.41 | G27: =elecPrice*G11 -> 801.36
A28: 水費(円/kg) | C28: =waterUse*waterPrice/1000*NM3perKG -> 4.6746 | D28: =waterUse*waterPrice/1000*NM3perKG -> 4.6746 | E28: =waterUse*waterPrice/1000*NM3perKG -> 4.6746 | F28: =waterUse*waterPrice/1000*NM3perKG -> 4.6746 | G28: =waterUse*waterPrice/1000*NM3perKG -> 4.6746
A29: 圧縮・出荷(円/kg) | C29: =C23 -> 0 | D29: =D23 -> 0 | E29: =E23 -> 0 | F29: =F23 -> 0 | G29: =G23 -> 0
A30: 補助金(円/kg) | C30: =-(subsidy*NM3perKG) -> 0 | D30: =-(subsidy*NM3perKG) -> 0 | E30: =-(subsidy*NM3perKG) -> 0 | F30: =-(subsidy*NM3perKG) -> 0 | G30: =-(subsidy*NM3perKG) -> 0
A31: 副生酸素(円/kg) | C31: =-(o2Credit*NM3perKG) -> 0 | D31: =-(o2Credit*NM3perKG) -> 0 | E31: =-(o2Credit*NM3perKG) -> 0 | F31: =-(o2Credit*NM3perKG) -> 0 | G31: =-(o2Credit*NM3perKG) -> 0
A32: 粗コスト合計(円/kg) | C32: =C24+C25+C26+C27+C28+C29 -> 1223.1232 | D32: =D24+D25+D26+D27+D28+D29 -> 1078.1696 | E32: =E24+E25+E26+E27+E28+E29 -> 1223.1232 | F32: =F24+F25+F26+F27+F28+F29 -> 1323.8488 | G32: =G24+G25+G26+G27+G28+G29 -> 1151.0378
A33: LCOH(円/kg) | C33: =C24+C25+C26+C27+C28+C29+C30+C31 -> 1223.1232 | D33: =D24+D25+D26+D27+D28+D29+D30+D31 -> 1078.1696 | E33: =E24+E25+E26+E27+E28+E29+E30+E31 -> 1223.1232 | F33: =F24+F25+F26+F27+F28+F29+F30+F31 -> 1323.8488 | G33: =G24+G25+G26+G27+G28+G29+G30+G31 -> 1151.0378
A34: LCOH(円/Nm³) | C34: =C33/NM3perKG -> 109.89426 | D34: =D33/NM3perKG -> 96.87058 | E34: =E33/NM3perKG -> 109.89426 | F34: =F33/NM3perKG -> 118.94418 | G34: =G33/NM3perKG -> 103.4176
A35: LCOH($/kg) | C35: =C33/fx -> 8.1541544 | D35: =D33/fx -> 7.187797 | E35: =E33/fx -> 8.1541544 | F35: =F33/fx -> 8.8256585 | G35: =G33/fx -> 7.6735856
A37: ▼ 積み上げグラフ用（円/Nm³）
A38: 成分＼方式 | C38: 現在 | D38: アルカリ | E38: PEM | F38: SOEC | G38: AEM
A39: 設備費(CAPEX) | C39: =C24/NM3perKG -> 23.190638 | D39: =D24/NM3perKG -> 17.540556 | E39: =E24/NM3perKG -> 23.190638 | F39: =F24/NM3perKG -> 35.24977 | G39: =G24/NM3perKG -> 18.889829
A40: スタック交換 | C40: =C25/NM3perKG -> 2.6847578 | D40: =D25/NM3perKG -> 1.3352772 | E40: =E25/NM3perKG -> 2.6847578 | F40: =F25/NM3perKG -> 11.336951 | G40: =G25/NM3perKG -> 6.1041934
A41: 固定O&M | C41: =C26/NM3perKG -> 8.5988684 | D41: =D26/NM3perKG -> 5.5747469 | E41: =E26/NM3perKG -> 8.5988684 | F41: =F26/NM3perKG -> 14.937463 | G41: =G26/NM3perKG -> 6.0035736
A42: 電力費 | C42: =C27/NM3perKG -> 75 | D42: =D27/NM3perKG -> 72 | E42: =E27/NM3perKG -> 75 | F42: =F27/NM3perKG -> 57 | G42: =G27/NM3perKG -> 72
...
